ERROR: [2023-01-21 06:33:24,858]  /home/.virtualenvs/photo/lib/python3.6/site-packages/django/utils/log.py, line 230, in log_response 
  "Internal Server Error: /"
Traceback (most recent call last):
  File "/home/.virtualenvs/photo/lib/python3.6/site-packages/django/core/handlers/exception.py", line 47, in inner
    response = get_response(request)
  File "/home/.virtualenvs/photo/lib/python3.6/site-packages/django/core/handlers/base.py", line 181, in _get_response
    response = wrapped_callback(request, *callback_args, **callback_kwargs)
  File "/home/photo/photos/views.py", line 61, in gallery
    1 /0
ZeroDivisionError: division by zero
ERROR: [2023-01-21 06:33:24,859]  /home/.virtualenvs/photo/lib/python3.6/site-packages/django/core/servers/basehttp.py, line 157, in log_message 
  ""GET / HTTP/1.1" 500 59584"
ERROR: [2023-02-11 05:12:49,980]  /Users/cheng/Library/Mobile Documents/com~apple~CloudDocs/iCloud/Develops/Project/gallery/venv/lib/python3.8/site-packages/django/utils/log.py, line 224, in log_response 
  "Internal Server Error: /"
Traceback (most recent call last):
  File "/Users/cheng/Library/Mobile Documents/com~apple~CloudDocs/iCloud/Develops/Project/gallery/venv/lib/python3.8/site-packages/django/db/backends/utils.py", line 84, in _execute
    return self.cursor.execute(sql, params)
  File "/Users/cheng/Library/Mobile Documents/com~apple~CloudDocs/iCloud/Develops/Project/gallery/venv/lib/python3.8/site-packages/django/db/backends/sqlite3/base.py", line 413, in execute
    return Database.Cursor.execute(self, query, params)
sqlite3.OperationalError: no such column: photos_photo.public

The above exception was the direct cause of the following exception:

Traceback (most recent call last):
  File "/Users/cheng/Library/Mobile Documents/com~apple~CloudDocs/iCloud/Develops/Project/gallery/venv/lib/python3.8/site-packages/django/core/handlers/exception.py", line 47, in inner
    response = get_response(request)
  File "/Users/cheng/Library/Mobile Documents/com~apple~CloudDocs/iCloud/Develops/Project/gallery/venv/lib/python3.8/site-packages/django/core/handlers/base.py", line 181, in _get_response
    response = wrapped_callback(request, *callback_args, **callback_kwargs)
  File "/Users/cheng/Library/Mobile Documents/com~apple~CloudDocs/iCloud/Develops/Project/gallery/photos/views.py", line 76, in gallery
    return render(request, 'photos/gallery.html', context)
  File "/Users/cheng/Library/Mobile Documents/com~apple~CloudDocs/iCloud/Develops/Project/gallery/venv/lib/python3.8/site-packages/django/shortcuts.py", line 19, in render
    content = loader.render_to_string(template_name, context, request, using=using)
  File "/Users/cheng/Library/Mobile Documents/com~apple~CloudDocs/iCloud/Develops/Project/gallery/venv/lib/python3.8/site-packages/django/template/loader.py", line 62, in render_to_string
    return template.render(context, request)
  File "/Users/cheng/Library/Mobile Documents/com~apple~CloudDocs/iCloud/Develops/Project/gallery/venv/lib/python3.8/site-packages/django/template/backends/django.py", line 61, in render
    return self.template.render(context)
  File "/Users/cheng/Library/Mobile Documents/com~apple~CloudDocs/iCloud/Develops/Project/gallery/venv/lib/python3.8/site-packages/django/template/base.py", line 170, in render
    return self._render(context)
  File "/Users/cheng/Library/Mobile Documents/com~apple~CloudDocs/iCloud/Develops/Project/gallery/venv/lib/python3.8/site-packages/django/template/base.py", line 162, in _render
    return self.nodelist.render(context)
  File "/Users/cheng/Library/Mobile Documents/com~apple~CloudDocs/iCloud/Develops/Project/gallery/venv/lib/python3.8/site-packages/django/template/base.py", line 938, in render
    bit = node.render_annotated(context)
  File "/Users/cheng/Library/Mobile Documents/com~apple~CloudDocs/iCloud/Develops/Project/gallery/venv/lib/python3.8/site-packages/django/template/base.py", line 905, in render_annotated
    return self.render(context)
  File "/Users/cheng/Library/Mobile Documents/com~apple~CloudDocs/iCloud/Develops/Project/gallery/venv/lib/python3.8/site-packages/django/template/defaulttags.py", line 168, in render
    len_values = len(values)
  File "/Users/cheng/Library/Mobile Documents/com~apple~CloudDocs/iCloud/Develops/Project/gallery/venv/lib/python3.8/site-packages/django/db/models/query.py", line 269, in __len__
    self._fetch_all()
  File "/Users/cheng/Library/Mobile Documents/com~apple~CloudDocs/iCloud/Develops/Project/gallery/venv/lib/python3.8/site-packages/django/db/models/query.py", line 1308, in _fetch_all
    self._result_cache = list(self._iterable_class(self))
  File "/Users/cheng/Library/Mobile Documents/com~apple~CloudDocs/iCloud/Develops/Project/gallery/venv/lib/python3.8/site-packages/django/db/models/query.py", line 53, in __iter__
    results = compiler.execute_sql(chunked_fetch=self.chunked_fetch, chunk_size=self.chunk_size)
  File "/Users/cheng/Library/Mobile Documents/com~apple~CloudDocs/iCloud/Develops/Project/gallery/venv/lib/python3.8/site-packages/django/db/models/sql/compiler.py", line 1156, in execute_sql
    cursor.execute(sql, params)
  File "/Users/cheng/Library/Mobile Documents/com~apple~CloudDocs/iCloud/Develops/Project/gallery/venv/lib/python3.8/site-packages/django/db/backends/utils.py", line 98, in execute
    return super().execute(sql, params)
  File "/Users/cheng/Library/Mobile Documents/com~apple~CloudDocs/iCloud/Develops/Project/gallery/venv/lib/python3.8/site-packages/django/db/backends/utils.py", line 66, in execute
    return self._execute_with_wrappers(sql, params, many=False, executor=self._execute)
  File "/Users/cheng/Library/Mobile Documents/com~apple~CloudDocs/iCloud/Develops/Project/gallery/venv/lib/python3.8/site-packages/django/db/backends/utils.py", line 75, in _execute_with_wrappers
    return executor(sql, params, many, context)
  File "/Users/cheng/Library/Mobile Documents/com~apple~CloudDocs/iCloud/Develops/Project/gallery/venv/lib/python3.8/site-packages/django/db/backends/utils.py", line 84, in _execute
    return self.cursor.execute(sql, params)
  File "/Users/cheng/Library/Mobile Documents/com~apple~CloudDocs/iCloud/Develops/Project/gallery/venv/lib/python3.8/site-packages/django/db/utils.py", line 90, in __exit__
    raise dj_exc_value.with_traceback(traceback) from exc_value
  File "/Users/cheng/Library/Mobile Documents/com~apple~CloudDocs/iCloud/Develops/Project/gallery/venv/lib/python3.8/site-packages/django/db/backends/utils.py", line 84, in _execute
    return self.cursor.execute(sql, params)
  File "/Users/cheng/Library/Mobile Documents/com~apple~CloudDocs/iCloud/Develops/Project/gallery/venv/lib/python3.8/site-packages/django/db/backends/sqlite3/base.py", line 413, in execute
    return Database.Cursor.execute(self, query, params)
django.db.utils.OperationalError: no such column: photos_photo.public
ERROR: [2023-02-11 05:12:49,982]  /Users/cheng/Library/Mobile Documents/com~apple~CloudDocs/iCloud/Develops/Project/gallery/venv/lib/python3.8/site-packages/django/core/servers/basehttp.py, line 157, in log_message 
  ""GET / HTTP/1.1" 500 171691"
ERROR: [2023-02-11 05:12:50,535]  /Users/cheng/Library/Mobile Documents/com~apple~CloudDocs/iCloud/Develops/Project/gallery/venv/lib/python3.8/site-packages/django/utils/log.py, line 224, in log_response 
  "Internal Server Error: /"
Traceback (most recent call last):
  File "/Users/cheng/Library/Mobile Documents/com~apple~CloudDocs/iCloud/Develops/Project/gallery/venv/lib/python3.8/site-packages/django/db/backends/utils.py", line 84, in _execute
    return self.cursor.execute(sql, params)
  File "/Users/cheng/Library/Mobile Documents/com~apple~CloudDocs/iCloud/Develops/Project/gallery/venv/lib/python3.8/site-packages/django/db/backends/sqlite3/base.py", line 413, in execute
    return Database.Cursor.execute(self, query, params)
sqlite3.OperationalError: no such column: photos_photo.public

The above exception was the direct cause of the following exception:

Traceback (most recent call last):
  File "/Users/cheng/Library/Mobile Documents/com~apple~CloudDocs/iCloud/Develops/Project/gallery/venv/lib/python3.8/site-packages/django/core/handlers/exception.py", line 47, in inner
    response = get_response(request)
  File "/Users/cheng/Library/Mobile Documents/com~apple~CloudDocs/iCloud/Develops/Project/gallery/venv/lib/python3.8/site-packages/django/core/handlers/base.py", line 181, in _get_response
    response = wrapped_callback(request, *callback_args, **callback_kwargs)
  File "/Users/cheng/Library/Mobile Documents/com~apple~CloudDocs/iCloud/Develops/Project/gallery/photos/views.py", line 76, in gallery
    return render(request, 'photos/gallery.html', context)
  File "/Users/cheng/Library/Mobile Documents/com~apple~CloudDocs/iCloud/Develops/Project/gallery/venv/lib/python3.8/site-packages/django/shortcuts.py", line 19, in render
    content = loader.render_to_string(template_name, context, request, using=using)
  File "/Users/cheng/Library/Mobile Documents/com~apple~CloudDocs/iCloud/Develops/Project/gallery/venv/lib/python3.8/site-packages/django/template/loader.py", line 62, in render_to_string
    return template.render(context, request)
  File "/Users/cheng/Library/Mobile Documents/com~apple~CloudDocs/iCloud/Develops/Project/gallery/venv/lib/python3.8/site-packages/django/template/backends/django.py", line 61, in render
    return self.template.render(context)
  File "/Users/cheng/Library/Mobile Documents/com~apple~CloudDocs/iCloud/Develops/Project/gallery/venv/lib/python3.8/site-packages/django/template/base.py", line 170, in render
    return self._render(context)
  File "/Users/cheng/Library/Mobile Documents/com~apple~CloudDocs/iCloud/Develops/Project/gallery/venv/lib/python3.8/site-packages/django/template/base.py", line 162, in _render
    return self.nodelist.render(context)
  File "/Users/cheng/Library/Mobile Documents/com~apple~CloudDocs/iCloud/Develops/Project/gallery/venv/lib/python3.8/site-packages/django/template/base.py", line 938, in render
    bit = node.render_annotated(context)
  File "/Users/cheng/Library/Mobile Documents/com~apple~CloudDocs/iCloud/Develops/Project/gallery/venv/lib/python3.8/site-packages/django/template/base.py", line 905, in render_annotated
    return self.render(context)
  File "/Users/cheng/Library/Mobile Documents/com~apple~CloudDocs/iCloud/Develops/Project/gallery/venv/lib/python3.8/site-packages/django/template/defaulttags.py", line 168, in render
    len_values = len(values)
  File "/Users/cheng/Library/Mobile Documents/com~apple~CloudDocs/iCloud/Develops/Project/gallery/venv/lib/python3.8/site-packages/django/db/models/query.py", line 269, in __len__
    self._fetch_all()
  File "/Users/cheng/Library/Mobile Documents/com~apple~CloudDocs/iCloud/Develops/Project/gallery/venv/lib/python3.8/site-packages/django/db/models/query.py", line 1308, in _fetch_all
    self._result_cache = list(self._iterable_class(self))
  File "/Users/cheng/Library/Mobile Documents/com~apple~CloudDocs/iCloud/Develops/Project/gallery/venv/lib/python3.8/site-packages/django/db/models/query.py", line 53, in __iter__
    results = compiler.execute_sql(chunked_fetch=self.chunked_fetch, chunk_size=self.chunk_size)
  File "/Users/cheng/Library/Mobile Documents/com~apple~CloudDocs/iCloud/Develops/Project/gallery/venv/lib/python3.8/site-packages/django/db/models/sql/compiler.py", line 1156, in execute_sql
    cursor.execute(sql, params)
  File "/Users/cheng/Library/Mobile Documents/com~apple~CloudDocs/iCloud/Develops/Project/gallery/venv/lib/python3.8/site-packages/django/db/backends/utils.py", line 98, in execute
    return super().execute(sql, params)
  File "/Users/cheng/Library/Mobile Documents/com~apple~CloudDocs/iCloud/Develops/Project/gallery/venv/lib/python3.8/site-packages/django/db/backends/utils.py", line 66, in execute
    return self._execute_with_wrappers(sql, params, many=False, executor=self._execute)
  File "/Users/cheng/Library/Mobile Documents/com~apple~CloudDocs/iCloud/Develops/Project/gallery/venv/lib/python3.8/site-packages/django/db/backends/utils.py", line 75, in _execute_with_wrappers
    return executor(sql, params, many, context)
  File "/Users/cheng/Library/Mobile Documents/com~apple~CloudDocs/iCloud/Develops/Project/gallery/venv/lib/python3.8/site-packages/django/db/backends/utils.py", line 84, in _execute
    return self.cursor.execute(sql, params)
  File "/Users/cheng/Library/Mobile Documents/com~apple~CloudDocs/iCloud/Develops/Project/gallery/venv/lib/python3.8/site-packages/django/db/utils.py", line 90, in __exit__
    raise dj_exc_value.with_traceback(traceback) from exc_value
  File "/Users/cheng/Library/Mobile Documents/com~apple~CloudDocs/iCloud/Develops/Project/gallery/venv/lib/python3.8/site-packages/django/db/backends/utils.py", line 84, in _execute
    return self.cursor.execute(sql, params)
  File "/Users/cheng/Library/Mobile Documents/com~apple~CloudDocs/iCloud/Develops/Project/gallery/venv/lib/python3.8/site-packages/django/db/backends/sqlite3/base.py", line 413, in execute
    return Database.Cursor.execute(self, query, params)
django.db.utils.OperationalError: no such column: photos_photo.public
ERROR: [2023-02-11 05:12:50,536]  /Users/cheng/Library/Mobile Documents/com~apple~CloudDocs/iCloud/Develops/Project/gallery/venv/lib/python3.8/site-packages/django/core/servers/basehttp.py, line 157, in log_message 
  ""GET / HTTP/1.1" 500 171342"
ERROR: [2023-02-11 06:03:19,997]  /Users/cheng/Library/Mobile Documents/com~apple~CloudDocs/iCloud/Develops/Project/gallery/venv/lib/python3.8/site-packages/django/utils/log.py, line 224, in log_response 
  "Internal Server Error: /login/"
Traceback (most recent call last):
  File "/Users/cheng/Library/Mobile Documents/com~apple~CloudDocs/iCloud/Develops/Project/gallery/venv/lib/python3.8/site-packages/django/core/handlers/exception.py", line 47, in inner
    response = get_response(request)
  File "/Users/cheng/Library/Mobile Documents/com~apple~CloudDocs/iCloud/Develops/Project/gallery/venv/lib/python3.8/site-packages/django/core/handlers/base.py", line 181, in _get_response
    response = wrapped_callback(request, *callback_args, **callback_kwargs)
  File "/Users/cheng/Library/Mobile Documents/com~apple~CloudDocs/iCloud/Develops/Project/gallery/photos/views.py", line 23, in login
    _next = request.GET.get('next', reverse('photo:gallery'))
  File "/Users/cheng/Library/Mobile Documents/com~apple~CloudDocs/iCloud/Develops/Project/gallery/venv/lib/python3.8/site-packages/django/urls/base.py", line 87, in reverse
    return iri_to_uri(resolver._reverse_with_prefix(view, prefix, *args, **kwargs))
  File "/Users/cheng/Library/Mobile Documents/com~apple~CloudDocs/iCloud/Develops/Project/gallery/venv/lib/python3.8/site-packages/django/urls/resolvers.py", line 685, in _reverse_with_prefix
    raise NoReverseMatch(msg)
django.urls.exceptions.NoReverseMatch: Reverse for 'gallery' with no arguments not found. 1 pattern(s) tried: ['gallery/(?P<username>[^/]+)/$']
ERROR: [2023-02-11 06:03:19,998]  /Users/cheng/Library/Mobile Documents/com~apple~CloudDocs/iCloud/Develops/Project/gallery/venv/lib/python3.8/site-packages/django/core/servers/basehttp.py, line 157, in log_message 
  ""POST /login/ HTTP/1.1" 500 78270"
WARNING: [2023-02-11 06:07:59,609]  /Users/cheng/Library/Mobile Documents/com~apple~CloudDocs/iCloud/Develops/Project/gallery/venv/lib/python3.8/site-packages/django/utils/log.py, line 224, in log_response 
  "Not Found: /gallery/public/"
WARNING: [2023-02-11 06:07:59,610]  /Users/cheng/Library/Mobile Documents/com~apple~CloudDocs/iCloud/Develops/Project/gallery/venv/lib/python3.8/site-packages/django/core/servers/basehttp.py, line 157, in log_message 
  ""GET /gallery/public/ HTTP/1.1" 404 3679"
WARNING: [2023-02-11 06:08:00,365]  /Users/cheng/Library/Mobile Documents/com~apple~CloudDocs/iCloud/Develops/Project/gallery/venv/lib/python3.8/site-packages/django/utils/log.py, line 224, in log_response 
  "Not Found: /gallery/public/"
WARNING: [2023-02-11 06:08:00,365]  /Users/cheng/Library/Mobile Documents/com~apple~CloudDocs/iCloud/Develops/Project/gallery/venv/lib/python3.8/site-packages/django/core/servers/basehttp.py, line 157, in log_message 
  ""GET /gallery/public/ HTTP/1.1" 404 3679"
